[2023-12-05 22:08:40,821] WARNING get_riscos() L150  Erro ao consultar os riscos com erro QueuePool limit of size 5 overflow 10 reached, connection timed out, timeout 30.00 (Background on this error at: https://sqlalche.me/e/20/3o7r), Não foi possível consultar os riscos:/QueuePool limit of size 5 overflow 10 reached, connection timed out, timeout 30.00 (Background on this error at: https://sqlalche.me/e/20/3o7r) - call_trace=C:\mvp\puc-rio-mvp-sprint-04-sistemas-inteligentes\projeto\API\app.py L150 
[2023-12-05 22:08:40,822] INFO _log() L96   127.0.0.1 - - [05/Dec/2023 22:08:40] "[35m[1mGET /riscos HTTP/1.1[0m" 500 - - call_trace=C:\mvp\puc-rio-mvp-sprint-04-sistemas-inteligentes\projeto\API\venv\Lib\site-packages\werkzeug\_internal.py L96  
[2023-12-05 22:08:40,828] INFO _log() L96   127.0.0.1 - - [05/Dec/2023 22:08:40] "[35m[1mGET /riscos HTTP/1.1[0m" 500 - - call_trace=C:\mvp\puc-rio-mvp-sprint-04-sistemas-inteligentes\projeto\API\venv\Lib\site-packages\werkzeug\_internal.py L96  
[2023-12-05 22:08:41,055] WARNING get_riscos() L150  Erro ao consultar os riscos com erro QueuePool limit of size 5 overflow 10 reached, connection timed out, timeout 30.00 (Background on this error at: https://sqlalche.me/e/20/3o7r), Não foi possível consultar os riscos:/QueuePool limit of size 5 overflow 10 reached, connection timed out, timeout 30.00 (Background on this error at: https://sqlalche.me/e/20/3o7r) - call_trace=C:\mvp\puc-rio-mvp-sprint-04-sistemas-inteligentes\projeto\API\app.py L150 
[2023-12-05 22:08:41,056] INFO _log() L96   127.0.0.1 - - [05/Dec/2023 22:08:41] "[35m[1mGET /riscos HTTP/1.1[0m" 500 - - call_trace=C:\mvp\puc-rio-mvp-sprint-04-sistemas-inteligentes\projeto\API\venv\Lib\site-packages\werkzeug\_internal.py L96  
[2023-12-05 22:08:58,305] WARNING get_riscos() L150  Erro ao consultar os riscos com erro QueuePool limit of size 5 overflow 10 reached, connection timed out, timeout 30.00 (Background on this error at: https://sqlalche.me/e/20/3o7r), Não foi possível consultar os riscos:/QueuePool limit of size 5 overflow 10 reached, connection timed out, timeout 30.00 (Background on this error at: https://sqlalche.me/e/20/3o7r) - call_trace=C:\mvp\puc-rio-mvp-sprint-04-sistemas-inteligentes\projeto\API\app.py L150 
[2023-12-05 22:08:58,306] INFO _log() L96   127.0.0.1 - - [05/Dec/2023 22:08:58] "[35m[1mGET /riscos HTTP/1.1[0m" 500 - - call_trace=C:\mvp\puc-rio-mvp-sprint-04-sistemas-inteligentes\projeto\API\venv\Lib\site-packages\werkzeug\_internal.py L96  
[2023-12-05 22:09:10,537] WARNING get_riscos() L150  Erro ao consultar os riscos com erro QueuePool limit of size 5 overflow 10 reached, connection timed out, timeout 30.00 (Background on this error at: https://sqlalche.me/e/20/3o7r), Não foi possível consultar os riscos:/QueuePool limit of size 5 overflow 10 reached, connection timed out, timeout 30.00 (Background on this error at: https://sqlalche.me/e/20/3o7r) - call_trace=C:\mvp\puc-rio-mvp-sprint-04-sistemas-inteligentes\projeto\API\app.py L150 
[2023-12-05 22:09:10,538] INFO _log() L96   127.0.0.1 - - [05/Dec/2023 22:09:10] "[35m[1mGET /riscos HTTP/1.1[0m" 500 - - call_trace=C:\mvp\puc-rio-mvp-sprint-04-sistemas-inteligentes\projeto\API\venv\Lib\site-packages\werkzeug\_internal.py L96  
[2023-12-05 22:09:10,805] WARNING get_riscos() L150  Erro ao consultar os riscos com erro QueuePool limit of size 5 overflow 10 reached, connection timed out, timeout 30.00 (Background on this error at: https://sqlalche.me/e/20/3o7r), Não foi possível consultar os riscos:/QueuePool limit of size 5 overflow 10 reached, connection timed out, timeout 30.00 (Background on this error at: https://sqlalche.me/e/20/3o7r) - call_trace=C:\mvp\puc-rio-mvp-sprint-04-sistemas-inteligentes\projeto\API\app.py L150 
[2023-12-05 22:09:10,806] INFO _log() L96   127.0.0.1 - - [05/Dec/2023 22:09:10] "[35m[1mGET /riscos HTTP/1.1[0m" 500 - - call_trace=C:\mvp\puc-rio-mvp-sprint-04-sistemas-inteligentes\projeto\API\venv\Lib\site-packages\werkzeug\_internal.py L96  
[2023-12-05 22:09:11,148] WARNING get_riscos() L150  Erro ao consultar os riscos com erro QueuePool limit of size 5 overflow 10 reached, connection timed out, timeout 30.00 (Background on this error at: https://sqlalche.me/e/20/3o7r), Não foi possível consultar os riscos:/QueuePool limit of size 5 overflow 10 reached, connection timed out, timeout 30.00 (Background on this error at: https://sqlalche.me/e/20/3o7r) - call_trace=C:\mvp\puc-rio-mvp-sprint-04-sistemas-inteligentes\projeto\API\app.py L150 
[2023-12-05 22:09:11,148] WARNING get_riscos() L150  Erro ao consultar os riscos com erro QueuePool limit of size 5 overflow 10 reached, connection timed out, timeout 30.00 (Background on this error at: https://sqlalche.me/e/20/3o7r), Não foi possível consultar os riscos:/QueuePool limit of size 5 overflow 10 reached, connection timed out, timeout 30.00 (Background on this error at: https://sqlalche.me/e/20/3o7r) - call_trace=C:\mvp\puc-rio-mvp-sprint-04-sistemas-inteligentes\projeto\API\app.py L150 
[2023-12-05 22:09:11,148] INFO _log() L96   127.0.0.1 - - [05/Dec/2023 22:09:11] "[35m[1mGET /riscos HTTP/1.1[0m" 500 - - call_trace=C:\mvp\puc-rio-mvp-sprint-04-sistemas-inteligentes\projeto\API\venv\Lib\site-packages\werkzeug\_internal.py L96  
[2023-12-05 22:09:11,149] INFO _log() L96   127.0.0.1 - - [05/Dec/2023 22:09:11] "[35m[1mGET /riscos HTTP/1.1[0m" 500 - - call_trace=C:\mvp\puc-rio-mvp-sprint-04-sistemas-inteligentes\projeto\API\venv\Lib\site-packages\werkzeug\_internal.py L96  
[2023-12-05 22:09:11,382] WARNING get_riscos() L150  Erro ao consultar os riscos com erro QueuePool limit of size 5 overflow 10 reached, connection timed out, timeout 30.00 (Background on this error at: https://sqlalche.me/e/20/3o7r), Não foi possível consultar os riscos:/QueuePool limit of size 5 overflow 10 reached, connection timed out, timeout 30.00 (Background on this error at: https://sqlalche.me/e/20/3o7r) - call_trace=C:\mvp\puc-rio-mvp-sprint-04-sistemas-inteligentes\projeto\API\app.py L150 
[2023-12-05 22:09:11,383] INFO _log() L96   127.0.0.1 - - [05/Dec/2023 22:09:11] "[35m[1mGET /riscos HTTP/1.1[0m" 500 - - call_trace=C:\mvp\puc-rio-mvp-sprint-04-sistemas-inteligentes\projeto\API\venv\Lib\site-packages\werkzeug\_internal.py L96  
[2023-12-05 22:12:27,304] WARNING get_riscos() L150  Erro ao consultar os riscos com erro QueuePool limit of size 5 overflow 10 reached, connection timed out, timeout 30.00 (Background on this error at: https://sqlalche.me/e/20/3o7r), Não foi possível consultar os riscos:/QueuePool limit of size 5 overflow 10 reached, connection timed out, timeout 30.00 (Background on this error at: https://sqlalche.me/e/20/3o7r) - call_trace=C:\mvp\puc-rio-mvp-sprint-04-sistemas-inteligentes\projeto\API\app.py L150 
[2023-12-05 22:12:27,307] INFO _log() L96   127.0.0.1 - - [05/Dec/2023 22:12:27] "[35m[1mGET /riscos HTTP/1.1[0m" 500 - - call_trace=C:\mvp\puc-rio-mvp-sprint-04-sistemas-inteligentes\projeto\API\venv\Lib\site-packages\werkzeug\_internal.py L96  
[2023-12-05 22:12:47,006] WARNING get_riscos() L150  Erro ao consultar os riscos com erro QueuePool limit of size 5 overflow 10 reached, connection timed out, timeout 30.00 (Background on this error at: https://sqlalche.me/e/20/3o7r), Não foi possível consultar os riscos:/QueuePool limit of size 5 overflow 10 reached, connection timed out, timeout 30.00 (Background on this error at: https://sqlalche.me/e/20/3o7r) - call_trace=C:\mvp\puc-rio-mvp-sprint-04-sistemas-inteligentes\projeto\API\app.py L150 
[2023-12-05 22:12:47,007] INFO _log() L96   127.0.0.1 - - [05/Dec/2023 22:12:47] "[35m[1mGET /riscos HTTP/1.1[0m" 500 - - call_trace=C:\mvp\puc-rio-mvp-sprint-04-sistemas-inteligentes\projeto\API\venv\Lib\site-packages\werkzeug\_internal.py L96  
[2023-12-05 22:12:57,629] WARNING get_riscos() L150  Erro ao consultar os riscos com erro QueuePool limit of size 5 overflow 10 reached, connection timed out, timeout 30.00 (Background on this error at: https://sqlalche.me/e/20/3o7r), Não foi possível consultar os riscos:/QueuePool limit of size 5 overflow 10 reached, connection timed out, timeout 30.00 (Background on this error at: https://sqlalche.me/e/20/3o7r) - call_trace=C:\mvp\puc-rio-mvp-sprint-04-sistemas-inteligentes\projeto\API\app.py L150 
[2023-12-05 22:12:57,631] INFO _log() L96   127.0.0.1 - - [05/Dec/2023 22:12:57] "[35m[1mGET /riscos HTTP/1.1[0m" 500 - - call_trace=C:\mvp\puc-rio-mvp-sprint-04-sistemas-inteligentes\projeto\API\venv\Lib\site-packages\werkzeug\_internal.py L96  
[2023-12-05 22:13:25,309] WARNING get_riscos() L150  Erro ao consultar os riscos com erro QueuePool limit of size 5 overflow 10 reached, connection timed out, timeout 30.00 (Background on this error at: https://sqlalche.me/e/20/3o7r), Não foi possível consultar os riscos:/QueuePool limit of size 5 overflow 10 reached, connection timed out, timeout 30.00 (Background on this error at: https://sqlalche.me/e/20/3o7r) - call_trace=C:\mvp\puc-rio-mvp-sprint-04-sistemas-inteligentes\projeto\API\app.py L150 
[2023-12-05 22:13:25,311] INFO _log() L96   127.0.0.1 - - [05/Dec/2023 22:13:25] "[35m[1mGET /riscos HTTP/1.1[0m" 500 - - call_trace=C:\mvp\puc-rio-mvp-sprint-04-sistemas-inteligentes\projeto\API\venv\Lib\site-packages\werkzeug\_internal.py L96  
[2023-12-05 22:13:27,943] WARNING get_riscos() L150  Erro ao consultar os riscos com erro QueuePool limit of size 5 overflow 10 reached, connection timed out, timeout 30.00 (Background on this error at: https://sqlalche.me/e/20/3o7r), Não foi possível consultar os riscos:/QueuePool limit of size 5 overflow 10 reached, connection timed out, timeout 30.00 (Background on this error at: https://sqlalche.me/e/20/3o7r) - call_trace=C:\mvp\puc-rio-mvp-sprint-04-sistemas-inteligentes\projeto\API\app.py L150 
